# 10.1 'try..catch'와 에러 핸들링

## 'try..catch' 문법

try...catch는 try 문에서 발생한 에러 잡아서 catch문으로 잔달하는 문법입니다.

try...catch는 오직 런타임 에러에만 동작합니다.

```js
// SyntaxError: Unexpected token 'catch'
try {
  {{{{{{{
  {{{{{{
  {{{{{
  {{{{
  {{{
  {{
  {
{
} catch (e) {
  console.log("에러가 발생했습니다!");
}
```

위처럼 문법적으로 잘못된 경우엔 실행하기 전에 에러가 발생하므로 try...catch가 작동하지 않습니다.

try...catch는 동기적으로 동작합니다.  
때문에 스케줄 된 코드에서 발생한 예외는 잡아낼 수 없습니다.

```js
try {
  setTimeout(() => {
    notDefinedVaraible; // ReferenceError: notDefinedVaraible is not defined
  }, 0);
} catch (e) {
  console.log("에러 발생");
}
```

때문에 스케줄 된 함수 내부에 try...catch를 써서 구현해야 합니다.

```js
setTimeout(() => {
  try {
    notDefinedVariable;
  } catch (e) {
    // 작동함
    console.log("에러 발생");
  }
}, 0);
```

## 에러 객체

자바스크립트는 에러가 발생하면 에러의 상세 내용이 담겨있는 에러 객체를 catch 문의 인수로 넘깁니다.  
내장 에러 전체와 에러 객체는 두 가지 프로퍼티를 가집니다.

- name: 에러 이름. RefeenceError나 TypeError 등이 있다.
- message: 에러 상세 내용을 담고 있는 문자 메시지

추가로 널리 사용되는 비표준 프로퍼티로 stack이 있습니다.

- stack: 현재 호출 스택. 에러를 유발한 중첩 호출들의 순서 정보를 갖는 문자열을 가진다.

```js
try {
  foo;
} catch (err) {
  console.log(err.name); // ReferenceError
  console.log(err.message); // foo is not defined
  console.log(err.stack); // ReferenceError: foo is not defined at ...
  // 그냥 에러 객체를 출력하면 name: message 형태의 문자열이 출력됩니다.
  console.log(err); // ReferenceError: foo is not defined
}
```

## 선택적 'catch' 바인딩

최근에 추가된 문법으로 구식 브라우저에선 폴리필이 필요합니다.

아래처럼 catch 문법 옆에 소괄호는 생략할 수 있습니다.

```js
try {
  // ...
} catch {
  // ...
}
```

## 직접 에러 만들어서 던지기

에러가 일어나야하는 상황이라면 직접 에러를 던져줄 수도 있습니다.

```js
throw <에러 객체>
```

이론적으론 throw엔 원시형 값도 들어갈 수 있지만 내장 에러와의 호환을 위해 에러 객체에다 메세지 인자를 넣어주는 것을 권장하고 있습니다.

## 에러 다시 던지기

에러 다시 던지기는 에러를 받은 catch 문에서 에러를 바깥으로 다시 던지는 것을 의미합니다.  
아래처럼 내가 잡으려는 에러가 아닐 때 밖으로 던지는 로직을 구현할 수 있습니다.

```js
try {
  ...
} catch(err) {
  if (err instanceof SyntaxError) {
    console.log("문법적인 오류가 발생했습니다!")
  } else {
    throw err
  }
}
```

이때 바깥에 try문이 있다면 그 구문에서 받은 에러를 catch문으로 던집니다.

## try, catch, finally

finally 절은 try문에서 에러가 발생하든 안하든 특정 코드를 무조건 실행하고 싶을 때 사용할 수 있습니다.

```js
try {
  ...
} catch {
  ...
} finally {
  // 에러가 뜨든 안뜨든 무조건 실행됨
}
```

## finally와 return

어떤 함수에 try, catch문에서 return으로 함수를 빠져나가는 구문이 있어도 finally 문은 무조건 실행됩니다.  
아래의 코드에선 finally에 console.log()가 먼저 실행된 후 바깥에 console.log()가 실행됩니다.

```js
function foo() {
  try {
    return 123;
  } catch {
  } finally {
    console.log(456); // 456
  }
}

console.log(foo()); // 123

/*
출력 결과:
456
123
*/
```

## try, finally

에러 때문에 스크립트가 죽더라도 죽기 전에 어떤 일을 하고 싶다면 catch문 없이 try, finally문 만 사용하면 됩니다.

```js
try {
  throw new Error("에러 발생!");
} finally {
  console.log("죽기 1초 전...");
}

/*
실행 결과:
죽기 1초 전...
Uncaught Error: 에러 발생!
    at <anonymous>:2:9
*/
```

## 전역 catch

만약 try...catch문 바깥에 에러가 터져서 스크립트가 죽었을 때 이걸 따로 사용자에게 보여주고 싶을 수 있습니다.  
만약 브라우저 환경에서 사용자에게 보여주고 싶다면 `window.onerror` 메서드를 사용하면 됩니다.

```js
window.onerror = function (message, url, line, col, error) {};
```

이때 함수의 매개변수에는 각각 에러 메시지, 에러가 발생한 스크립트 url, 에러가 발생한 줄과 열 번호, 에러 객체가 들어갑니다.

window.onerror는 죽은 스크립트를 복구하진 못합니다.  
window.onerror는 개발자에게 에러 메시지를 보내는 용도로 사용됩니다.
